2022-02-14 00:24:20,373 INFO    MainThread:29118 [internal.py:wandb_internal():92] W&B internal server running at pid: 29118, started at: 2022-02-14 00:24:20.373155
2022-02-14 00:24:20,382 DEBUG   HandlerThread:29118 [handler.py:handle_request():131] handle_request: run_start
2022-02-14 00:24:20,384 INFO    WriterThread:29118 [datastore.py:open_for_write():77] open: /home/pi/FedML-Server/executor/wandb/offline-run-20220214_002418-lf246rou/run-lf246rou.wandb
2022-02-14 00:24:20,388 DEBUG   HandlerThread:29118 [meta.py:__init__():36] meta init
2022-02-14 00:24:20,388 DEBUG   HandlerThread:29118 [meta.py:__init__():50] meta init done
2022-02-14 00:24:20,389 DEBUG   HandlerThread:29118 [meta.py:probe():210] probe
2022-02-14 00:24:20,392 DEBUG   HandlerThread:29118 [meta.py:_setup_git():200] setup git
2022-02-14 00:24:20,421 DEBUG   HandlerThread:29118 [meta.py:_setup_git():207] setup git done
2022-02-14 00:24:20,422 DEBUG   HandlerThread:29118 [meta.py:_save_pip():54] save pip
2022-02-14 00:24:20,423 DEBUG   HandlerThread:29118 [meta.py:_save_pip():68] save pip done
2022-02-14 00:24:20,423 DEBUG   HandlerThread:29118 [meta.py:probe():248] probe done
2022-02-14 00:29:03,337 WARNING MainThread:29118 [internal.py:wandb_internal():152] Internal process interrupt: 1
2022-02-14 00:29:03,936 WARNING MainThread:29118 [internal.py:wandb_internal():152] Internal process interrupt: 2
2022-02-14 00:29:03,937 ERROR   MainThread:29118 [internal.py:wandb_internal():155] Internal process interrupted.
2022-02-14 00:29:04,377 INFO    WriterThread:29118 [datastore.py:close():281] close: /home/pi/FedML-Server/executor/wandb/offline-run-20220214_002418-lf246rou/run-lf246rou.wandb
2022-02-14 00:29:04,392 INFO    HandlerThread:29118 [handler.py:finish():739] shutting down handler
2022-02-14 00:29:04,440 INFO    SenderThread:29118 [sender.py:finish():1075] shutting down sender
2022-02-14 00:29:04,440 INFO    MainThread:29118 [internal.py:handle_exit():79] Internal process exited
